Traceback (most recent call last):
  File "/home/runner/.cache/pypoetry/virtualenvs/customer-base-analysis-F-W2gxNr-py3.10/lib/python3.10/site-packages/jupyter_cache/executors/utils.py", line 58, in single_nb_execution
    executenb(
  File "/home/runner/.cache/pypoetry/virtualenvs/customer-base-analysis-F-W2gxNr-py3.10/lib/python3.10/site-packages/nbclient/client.py", line 1314, in execute
    return NotebookClient(nb=nb, resources=resources, km=km, **kwargs).execute()
  File "/home/runner/.cache/pypoetry/virtualenvs/customer-base-analysis-F-W2gxNr-py3.10/lib/python3.10/site-packages/jupyter_core/utils/__init__.py", line 173, in wrapped
    return loop.run_until_complete(inner)
  File "/opt/hostedtoolcache/Python/3.10.13/x64/lib/python3.10/asyncio/base_events.py", line 649, in run_until_complete
    return future.result()
  File "/home/runner/.cache/pypoetry/virtualenvs/customer-base-analysis-F-W2gxNr-py3.10/lib/python3.10/site-packages/nbclient/client.py", line 709, in async_execute
    await self.async_execute_cell(
  File "/home/runner/.cache/pypoetry/virtualenvs/customer-base-analysis-F-W2gxNr-py3.10/lib/python3.10/site-packages/nbclient/client.py", line 1062, in async_execute_cell
    await self._check_raise_for_error(cell, cell_index, exec_reply)
  File "/home/runner/.cache/pypoetry/virtualenvs/customer-base-analysis-F-W2gxNr-py3.10/lib/python3.10/site-packages/nbclient/client.py", line 918, in _check_raise_for_error
    raise CellExecutionError.from_cell_and_msg(cell, exec_reply_content)
nbclient.exceptions.CellExecutionError: An error occurred while executing the following cell:
------------------
import statistics

import matplotlib.pyplot as plt
import numpy as np
import pandas as pd
import seaborn as sns
import statsmodels.api as sm
import statsmodels.stats.api as sms
import xgboost
from keras import layers
from scipy import stats
from scipy.stats import boxcox, kstest, pearsonr, poisson
from sklearn.cross_decomposition import PLSRegression
from sklearn.ensemble import RandomForestClassifier
from sklearn.inspection import permutation_importance
from sklearn.linear_model import LinearRegression, PoissonRegressor
from sklearn.metrics import mean_absolute_error, mean_squared_error
from sklearn.model_selection import GridSearchCV, train_test_split
from sklearn.preprocessing import OrdinalEncoder, PolynomialFeatures, RobustScaler
from statsmodels.compat import lzip
from statsmodels.graphics.regressionplots import *
from statsmodels.stats.outliers_influence import variance_inflation_factor
from tensorflow import keras

from functions import affiche_score
from src.config import data_folder
from src.constants import var_categoriques, var_numeriques
from src.utils import init_notebook
------------------

----- stderr -----
2023-12-17 21:40:41.689594: I external/local_tsl/tsl/cuda/cudart_stub.cc:31] Could not find cuda drivers on your machine, GPU will not be used.
2023-12-17 21:40:41.721293: E external/local_xla/xla/stream_executor/cuda/cuda_dnn.cc:9261] Unable to register cuDNN factory: Attempting to register factory for plugin cuDNN when one has already been registered
2023-12-17 21:40:41.721328: E external/local_xla/xla/stream_executor/cuda/cuda_fft.cc:607] Unable to register cuFFT factory: Attempting to register factory for plugin cuFFT when one has already been registered
2023-12-17 21:40:41.722546: E external/local_xla/xla/stream_executor/cuda/cuda_blas.cc:1515] Unable to register cuBLAS factory: Attempting to register factory for plugin cuBLAS when one has already been registered
2023-12-17 21:40:41.728328: I external/local_tsl/tsl/cuda/cudart_stub.cc:31] Could not find cuda drivers on your machine, GPU will not be used.
2023-12-17 21:40:41.728841: I tensorflow/core/platform/cpu_feature_guard.cc:182] This TensorFlow binary is optimized to use available CPU instructions in performance-critical operations.
To enable the following instructions: AVX2 FMA, in other operations, rebuild TensorFlow with the appropriate compiler flags.
----- stderr -----
2023-12-17 21:40:42.596937: W tensorflow/compiler/tf2tensorrt/utils/py_utils.cc:38] TF-TRT Warning: Could not find TensorRT
------------------

[0;31m---------------------------------------------------------------------------[0m
[0;31mModuleNotFoundError[0m                       Traceback (most recent call last)
Cell [0;32mIn[1], line 25[0m
[1;32m     22[0m [38;5;28;01mfrom[39;00m [38;5;21;01mstatsmodels[39;00m[38;5;21;01m.[39;00m[38;5;21;01mstats[39;00m[38;5;21;01m.[39;00m[38;5;21;01moutliers_influence[39;00m [38;5;28;01mimport[39;00m variance_inflation_factor
[1;32m     23[0m [38;5;28;01mfrom[39;00m [38;5;21;01mtensorflow[39;00m [38;5;28;01mimport[39;00m keras
[0;32m---> 25[0m [38;5;28;01mfrom[39;00m [38;5;21;01mfunctions[39;00m [38;5;28;01mimport[39;00m affiche_score
[1;32m     26[0m [38;5;28;01mfrom[39;00m [38;5;21;01msrc[39;00m[38;5;21;01m.[39;00m[38;5;21;01mconfig[39;00m [38;5;28;01mimport[39;00m data_folder
[1;32m     27[0m [38;5;28;01mfrom[39;00m [38;5;21;01msrc[39;00m[38;5;21;01m.[39;00m[38;5;21;01mconstants[39;00m [38;5;28;01mimport[39;00m var_categoriques, var_numeriques

[0;31mModuleNotFoundError[0m: No module named 'functions'

